Workbook
Name Slicer_Year: #N/A

Sheet Income statement
A1: Income statement Grupo Bimbo
B3: 2022 | C3: 2023 | D3: 2024
A4: Revenue
A5: Sales | B5: 398706 | C5: 399879 | D5: 408335
A6: Cost of sales | B6: 193325 | C6: 194369 | D6: 193407
A7: Gross Profit | B7: =B5-B6 -> 205381 | C7: =C5-C6 -> 205510 | D7: =D5-D6 -> 214928
A9: Operating Expenses
A10: Distribution and selling Expenses | B10: 140455 | C10: 139477 | D10: 147628
A11: Administrative Expenses | B11: 26172 | C11: 25860 | D11: 27536
A12: Integration Expenses | B12: 367 | C12: 288 | D12: 317
A13: Othe Income (Expenses), Net | B13: -15309 | C13: 4430 | D13: 6298
A14: EBIT | B14: =B7-(SUM(B10:B13)) -> 53696 | C14: =C7-(SUM(C10:C13)) -> 35455 | D14: =D7-(SUM(D10:D13)) -> 33149
A16: Interest Expense | B16: 8049 | C16: 10006 | D16: 13100
A17: Interest Income | B17: -740 | C17: -809 | D17: -924
A18: Foreign Exhange Loss, Net | B18: 995 | C18: 1323 | D18: 506
A19: Monetary Position Gain | B19: -34 | C19: -73 | D19: -103
A20: Comprehensive Financing Result | B20: =SUM(B16:B19) -> 8270 | C20: =SUM(C16:C19) -> 10447 | D20: =SUM(D16:D19) -> 12579
A21: Share of Results of Associates | B21: 452 | C21: 316 | D21: 464
A22: EBITDA | B22: =B14-B20+B21 -> 45878 | C22: =C14-C20+C21 -> 25324 | D22: =D14-D20+D21 -> 21034
A24: Current Income Tax | B24: 9938 | C24: 9462 | D24: 7825
A25: Deferred Tax | B25: 4443 | C25: -1076 | D25: -1028
A26: Income Tax | B26: =SUM(B24:B25) -> 14381 | C26: =SUM(C24:C25) -> 8386 | D26: =SUM(D24:D25) -> 6797
A27: Net income from discontinued operations (after Tax) | B27: 16988 | C27: -16 | D27: -194
A28: Net Income | B28: =B22-B26+B27 -> 48485 | C28: =C22-C26+C27 -> 16922 | D28: =D22-D26+D27 -> 14043
A30: Controlling Interest | B30: 46910 | C30: 15477 | D30: 12544
A31: Non Controlling Interest | B31: 1575 | C31: 1445 | D31: 1499
A32: Basic Earning per Share | B32: 10.54 | C32: 3.5 | D32: 2.92
A33: Divident Per Share | B33: 0.65 | C33: 0.78 | D33: 0.94
A34: Adjusted EBITDA | B34: 53446 | C34: 54942 | D34: 55473

Sheet Balance Sheet
A1: Balance Sheet Grupo Bimbo
B2: 2022 | C2: 2023 | D2: 2024
A3: Assets
A4: Cash and Cash Equivalents | B4: 12313 | C4: 6353 | D4: 8057
A5: Accounts Receivable and Other Receivables, Net | B5: 32185 | C5: 33269 | D5: 36659
A6: Inventories | B6: 16989 | C6: 16120 | D6: 18832
A7: Prepaid Expenses | B7: 928 | C7: 1378 | D7: 1371
A8: Derivative Financial Instruments | B8: 38 | C8: 119 | D8: 1417
A9: Derivative Margin Deposits | B9: 879 | C9: 1519 | D9: 577
A10: Assets Held for Sale | B10: 138 | C10: 156 | D10: 267
A11: Total Current Assets | B11: =SUM(B4:B10) -> 63470 | C11: =SUM(C4:C10) -> 58914 | D11: =SUM(D4:D10) -> 67180
A13: Non-Current Assets
A14: Property, plant and Equipment, Net | B14: 113505 | C14: 129156 | D14: 155376
A15: Right of Use Assets, Net | B15: 28477 | C15: 25848 | D15: 34220
A16: Investment in Associates | B16: 4398 | C16: 5031 | D16: 7531
A17: Derivative Financial Instruments | B17: 2005 | C17: 468 | D17: 784
A18: Deferred Income Tax Assets | B18: 3962 | C18: 7313 | D18: 6884
A19: Intangible Assets, Net | B19: 59062 | C19: 55101 | D19: 65808
A20: GoodWill | B20: 68085 | C20: 62000 | D20: 75100
A21: Other Assets, Net | B21: 4800 | C21: 4271 | D21: 3921
A22: Total Assets | B22: =SUM(B14:B21)+B11 -> 347764 | C22: =SUM(C14:C21)+C11 -> 348102 | D22: =SUM(D14:D21)+D11 -> 416804
A24: Current Liabilities
A25: Current Portion of Long Term Debt | B25: 6435 | C25: 12932 | D25: 4862
A26: Accounts Payable | B26: 44058 | C26: 40409 | D26: 40815
A27: Other Payables and Accrued liabilities | B27: 24198 | C27: 22072 | D27: 27280
A28: Lease Liabilities | B28: 5930 | C28: 5751 | D28: 7140
A29: Payables to related Parties | B29: 1240 | C29: 1412 | D29: 1260
A30: Income Taxes Payable | B30: 4604 | C30: 665 | D30: 1535
A31: Employee Profit Sharing | B31: 1811 | C31: 1787 | D31: 1752
A32: Derivative Financial Instruments | B32: 1458 | C32: 2164 | D32: 511
A33: Total Current liabilities | B33: =SUM(B25:B32) -> 89734 | C33: =SUM(C25:C32) -> 87192 | D33: =SUM(D25:D32) -> 85155
A35: Non-Current Liabilities
A36: Long Term Debt | B36: 77619 | C36: 97003 | D36: 146043
A37: Lease liabilities (Non current) | B37: 23255 | C37: 21064 | D37: 28661
A38: Derivative financial instruments | B38: 590 | C38: 1888 | D38: 689
A39: Employee Benefitss Obligations | B39: 9382 | C39: 7217 | D39: 6635
A40: Deferred Income Tax liabilities | B40: 7575 | C40: 9224 | D40: 8891
A41: Other Long term liabilities | B41: 12007 | C41: 12886 | D41: 13032
A42: Total liabilities | B42: =SUM(B36:B41)+B33 -> 220162 | C42: =SUM(C36:C41)+C33 -> 236474 | D42: =SUM(D36:D41)+D33 -> 289106
A44: Equity
...

Sheet Financial Ratios
A1: Financial Ratios
A2: Category | B2: Ratio | C2: 2022 | D2: 2023 | E2: 2024
A3: Liquidity | B3: Current Ratio | C3: ='Balance Sheet'!B11/'Balance Sheet'!B33 -> 0.70731272 | D3: ='Balance Sheet'!C11/'Balance Sheet'!C33 -> 0.67568126 | E3: ='Balance Sheet'!D11/'Balance Sheet'!D33 -> 0.78891433
A4: Solvency | B4: Debt to equity | C4: ='Balance Sheet'!B42/'Balance Sheet'!B47 -> 1.7253805 | D4: ='Balance Sheet'!C42/'Balance Sheet'!C47 -> 2.1184112 | E4: ='Balance Sheet'!D42/'Balance Sheet'!D47 -> 2.2639822
A5: Profitability | B5: Gross Margin | C5: =('Income statement'!B5-'Income statement'!B6)/'Income statement'!B5 -> 0.51511891 | D5: =('Income statement'!C5-'Income statement'!C6)/'Income statement'!C5 -> 0.51393046 | E5: =('Income statement'!D5-'Income statement'!D6)/'Income statement'!D5 -> 0.52635214
A6: Profitability | B6: Operating Margin | C6: ='Income statement'!B14/'Income statement'!B5 -> 0.13467568 | D6: ='Income statement'!C14/'Income statement'!C5 -> 0.088664321 | E6: ='Income statement'!D14/'Income statement'!D5 -> 0.081180893
A7: Profitability | B7: Net Margin | C7: ='Income statement'!B28/'Income statement'!B5 -> 0.1216059 | D7: ='Income statement'!C28/'Income statement'!C5 -> 0.042317801 | E7: ='Income statement'!D28/'Income statement'!D5 -> 0.03439088
A8: Profitability | B8: ROA | C8: ='Income statement'!B28/'Balance Sheet'!B22 -> 0.13941926 | D8: ='Income statement'!C28/'Balance Sheet'!C22 -> 0.048612188 | E8: ='Income statement'!D28/'Balance Sheet'!D22 -> 0.033692095
A9: Growth | B9: Revenue Growth | D9: =('Income statement'!C5-'Income statement'!B5)/'Income statement'!B5 -> 0.0029420174 | E9: =('Income statement'!D5-'Income statement'!C5)/'Income statement'!C5 -> 0.021146397
A12: Year | B12: Ratio | C12: Value
A13: 2022 | B13: Gross margin | C13: 0.51511891
A14: 2023 | B14: Gross margin | C14: 0.51393046
A15: 2024 | B15: Gross margin | C15: 0.52635214
A16: 2022 | B16: Operating Margin | C16: 0.13467568
A17: 2023 | B17: Operating Margin | C17: 0.088664321
A18: 2024 | B18: Operating Margin | C18: 0.081180893
A19: 2022 | B19: Net Margin | C19: 0.1216059
A20: 2023 | B20: Net Margin | C20: 0.042317801
A21: 2024 | B21: Net Margin | C21: 0.03439088 | F21: Gross margin | G21: Net Margin | H21: Operating Margin
A22: 2022 | B22: Current Ratio | C22: 0.70731272 | E22: Sum of Value | F22: 0.51511891 | G22: 0.1216059 | H22: 0.13467568
A23: 2022 | B23: Debt to equity | C23: 1.7253805
A24: 2022 | B24: ROA | C24: 0.13941926
A25: 2023 | B25: Current Ratio | C25: 0.67568126
A26: 2023 | B26: Debt to equity | C26: 2.1184112
A27: 2023 | B27: ROA | C27: 0.048612188 | E27: Sum of Value
A28: 2024 | B28: Current Ratio | C28: 0.78891433 | E28: Row Labels | F28: Current Ratio | G28: Debt to equity | H28: ROA
A29: 2024 | B29: Debt to equity | C29: 2.2639822 | E29: 2022 | F29: 0.70731272 | G29: 1.7253805 | H29: 0.13941926
A30: 2024 | B30: ROA | C30: 0.033692095
A31: 2023 | B31: Growth | C31: 0.0029420174
A32: 2024 | B32: Growth | C32: 0.021146397

Sheet Charts

Sheet Summary
A1: Key insights:
A2: Profitability declined significantly from 2022 to 2024, as both operating and net margins decreased, despite stable gross margins.
A3: Profitability declined significantly from 2022 to 2024, as both operating and net margins decreased, despite stable gross margins.
A4: The company increased its leverage over time, as shown by the rising debt-to-equity ratio, which may indicate higher financial risk.
A5: The current ratio remained below 1 in all periods, suggesting potential short-term liquidity pressure.
A6: Return on Assets (ROA) declined sharply, reflecting lower efficiency in generating profits from assets.
A7: Revenue growth remained positive but modest, indicating limited expansion despite increasing financial leverage.
A8: Conclusion:
A9: The company shows stable operational performance, as reflected in consistent gross margins. However, profitability has declined due to increasing operating and financial pressures. At the same time, rising leverage and low liquidity levels suggest higher financial risk. Although revenue continues to grow, the pace remains moderate, indicating limited expansion.
A10: Recommendations:
A11: • Improve cost control to stabilize operating and net margins
A12: • Evaluate debt levels to reduce financial risk and improve capital structure
... A14: • Explore growth opportunities to accelerate revenue expansion
